
    <?xml version="1.0" encoding="utf-8"?>
    <mujoco>
 
 
            <body childclass="robot0:link" name="Base/0" pos="0 0 0">
                <inertial diaginertia="0.1 0.1 0.1" mass="4" pos="-0.01 0 0"></inertial>
                <geom pos="0 0 0" size="0.0001 0.0001 0.0001" type="box" name="robot0:Base/0" material="robot0:gripper_finger_mat" condim="4" friction="1 1 1"></geom>
                
            <body childclass="robot0:slidePart" name="Base/0/0j" pos="0 0.0001 0">
                <inertial diaginertia="0.1 0.1 0.1" mass="4" pos="-0.01 0 0"></inertial>
                <joint axis="0 -1 0" name="robot0:Base/0/0j" range="-0.15 0.15"></joint>
                <geom pos="0.0081 0.0086 0.0356" size="0.0236 0.0406 0.0166" type="box" name="robot0:Base/0/0j" material="robot0:gripper_finger_mat" condim="4" friction="1.0 1.0 1.0"></geom>
                
            <body childclass="robot0:slidePart" name="Base/0/0j/0j" pos="0 0.040600000000000004 0">
                <inertial diaginertia="0.1 0.1 0.1" mass="4" pos="-0.01 0 0"></inertial>
                <joint axis="0 -1 0" name="robot0:Base/0/0j/0j" range="-0.15 0.15"></joint>
                <geom pos="0.0446 0.0496 0.0091" size="0.0291 0.0021 0.0416" type="box" name="robot0:Base/0/0j/0j" material="robot0:gripper_finger_mat" condim="4" friction="1.0 1.0 1.0"></geom>
                
            <body childclass="robot0:slidePart" name="Base/0/0j/0j/0j" pos="0 0 0.041600000000000005">
                <inertial diaginertia="0.1 0.1 0.1" mass="4" pos="-0.01 0 0"></inertial>
                <joint axis="0 -1 0" name="robot0:Base/0/0j/0j/0j" range="-0.15 0.15"></joint>
                <geom pos="0.0421 0.0096 0.0181" size="0.0326 0.0266 0.0486" type="box" name="robot0:Base/0/0j/0j/0j" material="robot0:gripper_finger_mat" condim="4" friction="1.0 1.0 1.0"></geom>
                
            </body>
        
            </body>
        
            </body>
        

            <body childclass="robot0:slidePart" name="Base/0/1j" pos="0 0 0.0001">
                <inertial diaginertia="0.1 0.1 0.1" mass="4" pos="-0.01 0 0"></inertial>
                <joint axis="0 -1 0" name="robot0:Base/0/1j" range="-0.15 0.15"></joint>
                <geom pos="0.0341 0.0281 0.0191" size="0.0386 0.0116 0.0031" type="box" name="robot0:Base/0/1j" material="robot0:gripper_finger_mat" condim="4" friction="1.0 1.0 1.0"></geom>
                
            <body childclass="robot0:hingePart" name="Base/0/1j/0j" pos="0 0.0116 0">
                <inertial diaginertia="0.1 0.1 0.1" mass="4" pos="-0.01 0 0"></inertial>
                <joint axis="0 -1 0" name="robot0:Base/0/1j/0j" range="-0.75 0.75"></joint>
                <geom pos="0.0286 0.0046 0.0471" size="0.0296 0.0056 0.0481" type="box" name="robot0:Base/0/1j/0j" material="robot0:gripper_finger_mat" condim="4" friction="1.0 1.0 1.0"></geom>
                
            <body childclass="robot0:slidePart" name="Base/0/1j/0j/0j" pos="0.0296 0 0">
                <inertial diaginertia="0.1 0.1 0.1" mass="4" pos="-0.01 0 0"></inertial>
                <joint axis="0 -1 0" name="robot0:Base/0/1j/0j/0j" range="-0.15 0.15"></joint>
                <geom pos="0.0021 0.0276 0.0166" size="0.0496 0.0231 0.0321" type="box" name="robot0:Base/0/1j/0j/0j" material="robot0:gripper_finger_mat" condim="4" friction="1.0 1.0 1.0"></geom>
                
            </body>
        
            </body>
        
            </body>
        
            </body>
         
 
    </mujoco>
