
    <?xml version="1.0" encoding="utf-8"?>
    <mujoco>
 
 
            <body childclass="robot0:link" name="Base/0" pos="0 0 0">
                <inertial diaginertia="0.1 0.1 0.1" mass="4" pos="-0.01 0 0"></inertial>
                <geom pos="0 0 0" size="0.0001 0.0001 0.0001" type="box" name="robot0:Base/0" material="robot0:gripper_finger_mat" condim="4" friction="1 1 1"></geom>
                
            <body childclass="robot0:hingePart" name="Base/0/0j" pos="0 0 0.0001">
                <inertial diaginertia="0.1 0.1 0.1" mass="4" pos="-0.01 0 0"></inertial>
                <joint axis="0 -1 0" name="robot0:Base/0/0j" range="-0.75 0.75"></joint>
                <geom pos="0.0001 0.0051 0.0001" size="0.0001 0.0051 0.0001" type="box" name="robot0:Base/0/0j" material="robot0:gripper_finger_mat" condim="4" friction="1.0 1.0 1.0"></geom>
                
            <body childclass="robot0:slidePart" name="Base/0/0j/0j" pos="0.0001 0 0">
                <inertial diaginertia="0.1 0.1 0.1" mass="4" pos="-0.01 0 0"></inertial>
                <joint axis="0 -1 0" name="robot0:Base/0/0j/0j" range="-0.15 0.15"></joint>
                <geom pos="0.0001 0.0051 0.0051" size="0.0001 0.0051 0.0001" type="box" name="robot0:Base/0/0j/0j" material="robot0:gripper_finger_mat" condim="4" friction="1.0 1.0 1.0"></geom>
                
            <body childclass="robot0:hingePart" name="Base/0/0j/0j/0j" pos="0.0001 0 0">
                <inertial diaginertia="0.1 0.1 0.1" mass="4" pos="-0.01 0 0"></inertial>
                <joint axis="0 -1 0" name="robot0:Base/0/0j/0j/0j" range="-0.75 0.75"></joint>
                <geom pos="0.0001 0.0051 0.0051" size="0.0001 0.0001 0.0001" type="box" name="robot0:Base/0/0j/0j/0j" material="robot0:gripper_finger_mat" condim="4" friction="1.0 1.0 1.0"></geom>
                
            </body>
        
            </body>
        
            </body>
        

            <body childclass="robot0:hingePart" name="Base/0/1j" pos="0 0 0.0001">
                <inertial diaginertia="0.1 0.1 0.1" mass="4" pos="-0.01 0 0"></inertial>
                <joint axis="0 -1 0" name="robot0:Base/0/1j" range="-0.75 0.75"></joint>
                <geom pos="0.0001 0.0001 0.0051" size="0.0001 0.0001 0.0001" type="box" name="robot0:Base/0/1j" material="robot0:gripper_finger_mat" condim="4" friction="1.0 1.0 1.0"></geom>
                
            <body childclass="robot0:hingePart" name="Base/0/1j/0j" pos="0.0001 0 0">
                <inertial diaginertia="0.1 0.1 0.1" mass="4" pos="-0.01 0 0"></inertial>
                <joint axis="0 -1 0" name="robot0:Base/0/1j/0j" range="-0.75 0.75"></joint>
                <geom pos="0.0051 0.0001 0.0051" size="0.0001 0.0001 0.0051" type="box" name="robot0:Base/0/1j/0j" material="robot0:gripper_finger_mat" condim="4" friction="1.0 1.0 1.0"></geom>
                
            <body childclass="robot0:slidePart" name="Base/0/1j/0j/0j" pos="0.0001 0 0">
                <inertial diaginertia="0.1 0.1 0.1" mass="4" pos="-0.01 0 0"></inertial>
                <joint axis="0 -1 0" name="robot0:Base/0/1j/0j/0j" range="-0.15 0.15"></joint>
                <geom pos="0.0001 0.0001 0.0001" size="0.0001 0.0001 0.0001" type="box" name="robot0:Base/0/1j/0j/0j" material="robot0:gripper_finger_mat" condim="4" friction="1.0 1.0 1.0"></geom>
                
            </body>
        
            </body>
        
            </body>
        
            </body>
         
 
    </mujoco>
