
    <?xml version="1.0" encoding="utf-8"?>
    <mujoco>
 
 
            <body childclass="robot0:link" name="Base/0" pos="0 0 0">
                <inertial diaginertia="0.1 0.1 0.1" mass="4" pos="-0.01 0 0"></inertial>
                <geom pos="0 0 0" size="0.0001 0.0001 0.0001" type="box" name="robot0:Base/0" material="robot0:gripper_finger_mat" condim="4" friction="1 1 1"></geom>
                
            <body childclass="robot0:hingePart" name="Base/0/0j" pos="0 0.0001 0">
                <inertial diaginertia="0.1 0.1 0.1" mass="4" pos="-0.01 0 0"></inertial>
                <joint axis="0 -1 0" name="robot0:Base/0/0j" range="-0.75 0.75"></joint>
                <geom pos="0.0041 0.0061 0.0146" size="0.0426 0.0291 0.0311" type="box" name="robot0:Base/0/0j" material="robot0:gripper_finger_mat" condim="4" friction="1.0 1.0 1.0"></geom>
                
            <body childclass="robot0:slidePart" name="Base/0/0j/0j" pos="0.042600000000000006 0 0">
                <inertial diaginertia="0.1 0.1 0.1" mass="4" pos="-0.01 0 0"></inertial>
                <joint axis="0 -1 0" name="robot0:Base/0/0j/0j" range="-0.15 0.15"></joint>
                <geom pos="0.0461 0.0341 0.0066" size="0.0381 0.0351 0.0256" type="box" name="robot0:Base/0/0j/0j" material="robot0:gripper_finger_mat" condim="4" friction="1.0 1.0 1.0"></geom>
                
            <body childclass="robot0:hingePart" name="Base/0/0j/0j/0j" pos="0.0381 0 0">
                <inertial diaginertia="0.1 0.1 0.1" mass="4" pos="-0.01 0 0"></inertial>
                <joint axis="0 -1 0" name="robot0:Base/0/0j/0j/0j" range="-0.75 0.75"></joint>
                <geom pos="0.0026 0.0446 0.0386" size="0.0421 0.0496 0.0391" type="box" name="robot0:Base/0/0j/0j/0j" material="robot0:gripper_finger_mat" condim="4" friction="1.0 1.0 1.0"></geom>
                
            </body>
        
            </body>
        
            </body>
        

            <body childclass="robot0:hingePart" name="Base/0/1j" pos="0 0.0001 0">
                <inertial diaginertia="0.1 0.1 0.1" mass="4" pos="-0.01 0 0"></inertial>
                <joint axis="0 -1 0" name="robot0:Base/0/1j" range="-0.75 0.75"></joint>
                <geom pos="0.0386 0.0161 0.0056" size="0.0431 0.0381 0.0031" type="box" name="robot0:Base/0/1j" material="robot0:gripper_finger_mat" condim="4" friction="1.0 1.0 1.0"></geom>
                
            <body childclass="robot0:hingePart" name="Base/0/1j/0j" pos="0.043100000000000006 0 0">
                <inertial diaginertia="0.1 0.1 0.1" mass="4" pos="-0.01 0 0"></inertial>
                <joint axis="0 -1 0" name="robot0:Base/0/1j/0j" range="-0.75 0.75"></joint>
                <geom pos="0.0106 0.0126 0.0141" size="0.0491 0.0466 0.0451" type="box" name="robot0:Base/0/1j/0j" material="robot0:gripper_finger_mat" condim="4" friction="1.0 1.0 1.0"></geom>
                
            <body childclass="robot0:slidePart" name="Base/0/1j/0j/0j" pos="0 0.0466 0">
                <inertial diaginertia="0.1 0.1 0.1" mass="4" pos="-0.01 0 0"></inertial>
                <joint axis="0 -1 0" name="robot0:Base/0/1j/0j/0j" range="-0.15 0.15"></joint>
                <geom pos="0.0211 0.0266 0.0391" size="0.0476 0.0451 0.0071" type="box" name="robot0:Base/0/1j/0j/0j" material="robot0:gripper_finger_mat" condim="4" friction="1.0 1.0 1.0"></geom>
                
            </body>
        
            </body>
        
            </body>
        
            </body>
         
 
    </mujoco>
